Workbook

Sheet REMISIÓN 2024
A2: REMISIÓN DE MUESTRAS
K3: F9T09-02
F4: FECHA DE ELABORACIÓN | G4: =TODAY() -> 46217 | I4: CONSECUTIVO | J4: 29
B7: LABORATORIO DE ENSAYOS NYCE COLOMBIA S.A.S
B9: CLIENTE | D9: =_xlfn.XLOOKUP(M12,#REF!,#REF!) -> #REF! | G9: TIPO DE SALIDA | I9: RECOLECCIÓN POR PARTE DEL CLIENTE
B11: IDENTIFICACIÓN INTERNA | D11: IDENTIFICACIÓN EXTERNA | E11: DESCRIPCIÓN | G11: FABRICANTE /MARCA | H11: OBSERVACIONES | J11: FECHA DE RECEPCIÓN | K11: FECHA DE ENTREGA | M11: PEGAR AQUÍ ÍTEM ︾
B12: Varios | D12: =IF(M12>0,(UPPER(_xlfn.XLOOKUP(M12,#REF!,#REF!,"No encontrado",0))),"") -> #REF! | E12: =IF(M12>0,(PROPER(_xlfn.XLOOKUP(M12,#REF!,#REF!,"No encontrado",0))),"") -> #REF! | G12: =IF(M12>0,(PROPER(_xlfn.XLOOKUP(M12,#REF!,#REF!,"No encontrado",0))),"") -> #REF! | H12: Ninguna | J12: 45636 | K12: 45714 | M12: 370
B13: Varios | D13: =IF(M13>0,(UPPER(_xlfn.XLOOKUP(M13,#REF!,#REF!,"No encontrado",0))),"") -> #REF! | E13: =IF(M13>0,(PROPER(_xlfn.XLOOKUP(M13,#REF!,#REF!,"No encontrado",0))),"") -> #REF! | G13: =IF(M13>0,(PROPER(_xlfn.XLOOKUP(M13,#REF!,#REF!,"No encontrado",0))),"") -> #REF! | H13: Ninguna | J13: 45636 | K13: 45714 | M13: 371 | S13: SI(M12>0;BUSCARX(M12;DATOS!B:B;DATOS!A:A;"";0);"")
B14: Varios | D14: =IF(M14>0,(UPPER(_xlfn.XLOOKUP(M14,#REF!,#REF!,"No encontrado",0))),"") -> #REF! | E14: =IF(M14>0,(PROPER(_xlfn.XLOOKUP(M14,#REF!,#REF!,"No encontrado",0))),"") -> #REF! | G14: =IF(M14>0,(PROPER(_xlfn.XLOOKUP(M14,#REF!,#REF!,"No encontrado",0))),"") -> #REF! | H14: Ninguna | J14: 45636 | K14: 45714 | M14: 372
B15: Varios | D15: =IF(M15>0,(UPPER(_xlfn.XLOOKUP(M15,#REF!,#REF!,"No encontrado",0))),"") -> #REF! | E15: =IF(M15>0,(PROPER(_xlfn.XLOOKUP(M15,#REF!,#REF!,"No encontrado",0))),"") -> #REF! | G15: =IF(M15>0,(PROPER(_xlfn.XLOOKUP(M15,#REF!,#REF!,"No encontrado",0))),"") -> #REF! | H15: Ninguna | J15: =_xlfn.XLOOKUP(M15,#REF!,#REF!,0) -> #REF! | K15: =IF(M15>0,TODAY(),"") -> 46217 | M15: 373
B16: Varios | D16: =IF(M16>0,(UPPER(_xlfn.XLOOKUP(M16,#REF!,#REF!,"No encontrado",0))),"") -> #REF! | E16: =IF(M16>0,(PROPER(_xlfn.XLOOKUP(M16,#REF!,#REF!,"No encontrado",0))),"") -> #REF! | G16: =IF(M16>0,(PROPER(_xlfn.XLOOKUP(M16,#REF!,#REF!,"No encontrado",0))),"") -> #REF! | H16: Ninguna | J16: =_xlfn.XLOOKUP(M16,#REF!,#REF!,0) -> #REF! | K16: =IF(M16>0,TODAY(),"") -> 46217 | M16: 1607
B17: Varios | D17: =IF(M17>0,(UPPER(_xlfn.XLOOKUP(M17,#REF!,#REF!,"No encontrado",0))),"") -> #REF! | E17: =IF(M17>0,(PROPER(_xlfn.XLOOKUP(M17,#REF!,#REF!,"No encontrado",0))),"") -> #REF! | G17: =IF(M17>0,(PROPER(_xlfn.XLOOKUP(M17,#REF!,#REF!,"No encontrado",0))),"") -> #REF! | H17: Ninguna | J17: =_xlfn.XLOOKUP(M17,#REF!,#REF!,0) -> #REF! | K17: =IF(M17>0,TODAY(),"") -> 46217 | M17: 1608
B18: Varios | D18: =IF(M18>0,(UPPER(_xlfn.XLOOKUP(M18,#REF!,#REF!,"No encontrado",0))),"") -> #REF! | E18: =IF(M18>0,(PROPER(_xlfn.XLOOKUP(M18,#REF!,#REF!,"No encontrado",0))),"") -> #REF! | G18: =IF(M18>0,(PROPER(_xlfn.XLOOKUP(M18,#REF!,#REF!,"No encontrado",0))),"") -> #REF! | H18: Ninguna | J18: =_xlfn.XLOOKUP(M18,#REF!,#REF!,0) -> #REF! | K18: =IF(M18>0,TODAY(),"") -> 46217 | M18: 1609
B19: Varios | D19: =IF(M19>0,(UPPER(_xlfn.XLOOKUP(M19,#REF!,#REF!,"No encontrado",0))),"") -> #REF! | E19: =IF(M19>0,(PROPER(_xlfn.XLOOKUP(M19,#REF!,#REF!,"No encontrado",0))),"") -> #REF! | G19: =IF(M19>0,(PROPER(_xlfn.XLOOKUP(M19,#REF!,#REF!,"No encontrado",0))),"") -> #REF! | H19: Ninguna | J19: =_xlfn.XLOOKUP(M19,#REF!,#REF!,0) -> #REF! | K19: =IF(M19>0,TODAY(),"") -> 46217 | M19: 1610
B20: Varios | D20: =IF(M20>0,(UPPER(_xlfn.XLOOKUP(M20,#REF!,#REF!,"No encontrado",0))),"") -> #REF! | E20: =IF(M20>0,(PROPER(_xlfn.XLOOKUP(M20,#REF!,#REF!,"No encontrado",0))),"") -> #REF! | G20: =IF(M20>0,(PROPER(_xlfn.XLOOKUP(M20,#REF!,#REF!,"No encontrado",0))),"") -> #REF! | H20: Ninguna | J20: =_xlfn.XLOOKUP(M20,#REF!,#REF!,0) -> #REF! | K20: =IF(M20>0,TODAY(),"") -> 46217 | M20: 1611
B21: Varios | D21: =IF(M21>0,(UPPER(_xlfn.XLOOKUP(M21,#REF!,#REF!,"No encontrado",0))),"") -> #REF! | E21: =IF(M21>0,(PROPER(_xlfn.XLOOKUP(M21,#REF!,#REF!,"No encontrado",0))),"") -> #REF! | G21: =IF(M21>0,(PROPER(_xlfn.XLOOKUP(M21,#REF!,#REF!,"No encontrado",0))),"") -> #REF! | H21: Ninguna | J21: =_xlfn.XLOOKUP(M21,#REF!,#REF!,0) -> #REF! | K21: =IF(M21>0,TODAY(),"") -> 46217 | M21: 1612
B22: Varios | D22: =IF(M22>0,(UPPER(_xlfn.XLOOKUP(M22,#REF!,#REF!,"No encontrado",0))),"") -> #REF! | E22: =IF(M22>0,(PROPER(_xlfn.XLOOKUP(M22,#REF!,#REF!,"No encontrado",0))),"") -> #REF! | G22: =IF(M22>0,(PROPER(_xlfn.XLOOKUP(M22,#REF!,#REF!,"No encontrado",0))),"") -> #REF! | H22: Ninguna | J22: =_xlfn.XLOOKUP(M22,#REF!,#REF!,0) -> #REF! | K22: =IF(M22>0,TODAY(),"") -> 46217 | M22: 1613
B23: Varios | D23: =IF(M23>0,(UPPER(_xlfn.XLOOKUP(M23,#REF!,#REF!,"No encontrado",0))),"") -> #REF! | E23: =IF(M23>0,(PROPER(_xlfn.XLOOKUP(M23,#REF!,#REF!,"No encontrado",0))),"") -> #REF! | G23: =IF(M23>0,(PROPER(_xlfn.XLOOKUP(M23,#REF!,#REF!,"No encontrado",0))),"") -> #REF! | H23: Ninguna | J23: =_xlfn.XLOOKUP(M23,#REF!,#REF!,0) -> #REF! | K23: =IF(M23>0,TODAY(),"") -> 46217 | M23: 1614
B24: Varios | D24: =IF(M24>0,(UPPER(_xlfn.XLOOKUP(M24,#REF!,#REF!,"No encontrado",0))),"") -> #REF! | E24: =IF(M24>0,(PROPER(_xlfn.XLOOKUP(M24,#REF!,#REF!,"No encontrado",0))),"") -> #REF! | G24: =IF(M24>0,(PROPER(_xlfn.XLOOKUP(M24,#REF!,#REF!,"No encontrado",0))),"") -> #REF! | H24: Ninguna | J24: =_xlfn.XLOOKUP(M24,#REF!,#REF!,0) -> #REF! | K24: =IF(M24>0,TODAY(),"") -> 46217 | M24: 1615
B25: Varios | D25: =IF(M25>0,(UPPER(_xlfn.XLOOKUP(M25,#REF!,#REF!,"No encontrado",0))),"") -> #REF! | E25: =IF(M25>0,(PROPER(_xlfn.XLOOKUP(M25,#REF!,#REF!,"No encontrado",0))),"") -> #REF! | G25: =IF(M25>0,(PROPER(_xlfn.XLOOKUP(M25,#REF!,#REF!,"No encontrado",0))),"") -> #REF! | H25: Ninguna | J25: =_xlfn.XLOOKUP(M25,#REF!,#REF!,0) -> #REF! | K25: =IF(M25>0,TODAY(),"") -> 46217 | M25: 1616
B26: Varios | D26: =IF(M26>0,(UPPER(_xlfn.XLOOKUP(M26,#REF!,#REF!,"No encontrado",0))),"") -> #REF! | E26: =IF(M26>0,(PROPER(_xlfn.XLOOKUP(M26,#REF!,#REF!,"No encontrado",0))),"") -> #REF! | G26: =IF(M26>0,(PROPER(_xlfn.XLOOKUP(M26,#REF!,#REF!,"No encontrado",0))),"") -> #REF! | H26: Ninguna | J26: =_xlfn.XLOOKUP(M26,#REF!,#REF!,0) -> #REF! | K26: =IF(M26>0,TODAY(),"") -> 46217 | M26: 1617
B27: Varios | D27: =IF(M27>0,(UPPER(_xlfn.XLOOKUP(M27,#REF!,#REF!,"No encontrado",0))),"") -> #REF! | E27: =IF(M27>0,(PROPER(_xlfn.XLOOKUP(M27,#REF!,#REF!,"No encontrado",0))),"") -> #REF! | G27: =IF(M27>0,(PROPER(_xlfn.XLOOKUP(M27,#REF!,#REF!,"No encontrado",0))),"") -> #REF! | H27: Ninguna | J27: =_xlfn.XLOOKUP(M27,#REF!,#REF!,0) -> #REF! | K27: =IF(M27>0,TODAY(),"") -> 46217 | M27: 1643
H28: Se entrega todas las muestras incluidas las que no se ensayaron en nyce | J28: =_xlfn.XLOOKUP(M28,#REF!,#REF!,0) -> #REF! | K28: =IF(M28>0,TODAY(),"")
D29: =IF(M29>0,(UPPER(_xlfn.XLOOKUP(M29,#REF!,#REF!,"No encontrado",0))),"") | E29: =IF(M29>0,(PROPER(_xlfn.XLOOKUP(M29,#REF!,#REF!,"No encontrado",0))),"") | G29: =IF(M29>0,(PROPER(_xlfn.XLOOKUP(M29,#REF!,#REF!,"No encontrado",0))),"") | J29: =_xlfn.XLOOKUP(M29,#REF!,#REF!,0) -> #REF! | K29: =IF(M29>0,TODAY(),"")
J35: =_xlfn.XLOOKUP(M35,#REF!,#REF!,0) -> #REF! | K35: =IF(M35>0,TODAY(),"")
B37: TOTAL MUESTRAS | C37: 17 | D37: NUMERO DE EMPAQUES | E37: 17 | F37: OBSERVACIÓN FINAL DE LAS MUESTRAS | H37: Todas las muestras fueron ensayadas, por lo tanto, ninguna se encuentra en buen estado estético, debido al procedimiento de ensayo y manipulación de la muestra.
C40: ENTREGADO POR: | G40: ENTREGADO A: | M40: Todas las muestras fueron ensayadas, por lo tanto, ninguna se encuentra en buen estado, debido al procedimiento de ensayo y manipulación de la muestra.
G41: FIRMA
C42: Andres Carvajal | G42: NOMBRE
B44: ENTRADA EN VIGOR 2023-08-30
A45: Se prohíbe la reproducción total o parcial sin previa autorización
A46: NYCE Colombia S.A.S. | Calle 30 No. 17 - 52 | Teusaquillo - Bogotá D.C. Colombia | Tel. + 571 756 84 85 ext. 129
A51: REMISIÓN DE MUESTRAS
K52: F9T09-02
F53: FECHA DE ELABORACIÓN | G53: =G4 -> 46217 | I53: CONSECUTIVO | J53: =J4 -> 29
B56: LABORATORIO DE ENSAYOS NYCE COLOMBIA S.A.S
B58: CLIENTE | D58: =D9 -> #REF! | G58: TIPO DE SALIDA | I58: =I9 -> RECOLECCIÓN POR PARTE DEL CLIENTE
B60: IDENTIFICACIÓN INTERNA | D60: IDENTIFICACIÓN EXTERNA | E60: DESCRIPCIÓN | G60: FABRICANTE /MARCA | H60: OBSERVACIONES | J60: FECHA DE RECEPCIÓN | K60: FECHA DE ENTREGA
B61: =B12 -> Varios | D61: =D12 -> #REF! | E61: =E12 -> #REF! | G61: =G12 -> #REF! | H61: =H12 -> Ninguna | J61: =J12 -> 45636 | K61: =K12 -> 45714
B62: =B13 -> Varios | D62: =D13 -> #REF! | E62: =E13 -> #REF! | G62: =G13 -> #REF! | H62: =H13 -> Ninguna | J62: =J13 -> 45636 | K62: =K13 -> 45714
...

Sheet Hoja2

Sheet Hoja1
D1: Muestras para entregar
D5: 45701 | E5: INTERTEK | F5: Caja plastica azul | G5: ambar polar | H5: 25008 | I5: LENC | J5: 25 | K5: I 0083 | L5: 1 | M5: C 0089
D6: 45701 | E6: INTERTEK | F6: Caja plastica azul | G6: ambar polar | H6: 25009 | I6: LENC | J6: 25 | K6: I 0083 | L6: 1 | M6: C 0089
D7: 45701 | E7: INTERTEK | F7: Caja plastica azul | G7: ambar polar | H7: 25010 | I7: LENC | J7: 25 | K7: I 0083 | L7: 1 | M7: C 0089
D8: 45719 | E8: INTERTEK | F8: Bombillos E27 | G8: IKEA | H8: 20873 | I8: LENC | J8: 25 | K8: I 0057 / 0058 / 0059 / 0060 | L8: 2 | M8: C 0078
D9: 45719 | E9: INTERTEK | F9: Bombillos E27 | G9: IKEA | H9: 20872 | I9: LENC | J9: 25 | K9: I 0057 / 0058 / 0059 / 0060 | L9: 2 | M9: C 0078
D10: 45719 | E10: INTERTEK | F10: Bombillos E27 | G10: IKEA | H10: 20871 | I10: LENC | J10: 25 | K10: I 0057 / 0058 / 0059 / 0060 | L10: 2 | M10: C 0078
D11: 45719 | E11: INTERTEK | F11: Bombillo GU10 | G11: IKEA | H11: 20877 | I11: LENC | J11: 25 | K11: I 0057 / 0058 / 0059 / 0060 | L11: 2 | M11: C 0078
D12: 45719 | E12: INTERTEK | F12: Bombillo GU10 | G12: IKEA | H12: 20879 | I12: LENC | J12: 25 | K12: I 0057 / 0058 / 0059 / 0060 | L12: 2 | M12: C 0078
D13: 45719 | E13: INTERTEK | F13: Bombillo GU10 | G13: IKEA | H13: 20878 | I13: LENC | J13: 25 | K13: I 0057 / 0058 / 0059 / 0060 | L13: 2 | M13: C 0078
D14: 45719 | E14: INTERTEK | F14: Bombillo E14 | G14: IKEA | H14: 20868 | I14: LENC | J14: 25 | K14: I 0057 / 0058 / 0059 / 0060 | L14: 2 | M14: C 0078
D15: 45719 | E15: INTERTEK | F15: Bombillo E14 | G15: IKEA | H15: 20869 | I15: LENC | J15: 25 | K15: I 0057 / 0058 / 0059 / 0060 | L15: 2 | M15: C 0078
D16: 45719 | E16: INTERTEK | F16: Bombillo E14 | G16: IKEA | H16: 20870 | I16: LENC | J16: 25 | K16: I 0057 / 0058 / 0059 / 0060 | L16: 2 | M16: C 0078
... D30: 45588 | E30: Intertek | F30: Luminaria de colgar | G30: IKEA | H30: 21665 | I30: LENC | J30: 24 | K30: I 0996 | L30: 1 | M30: C 1209
D31: 45581 | E31: Intertek | F31: Riel blanco 3M | G31: N/E | H31: 21639 / 21640 | I31: LENC | J31: 24 | K31: I 0994 / 0995 | L31: 2 | M31: C 1225
D32: 45580 | E32: Intertek | F32: Conector de riel | G32: N/E | H32: 21633 | I32: LENC | J32: 24 | K32: N/E | L32: 1 | M32: N/E
D33: 45580 | E33: Intertek | F33: Conector de riel | G33: N/E | H33: 21629 | I33: LENC | J33: 24 | K33: N/E | L33: 1 | M33: N/E
D34: 45580 | E34: Intertek | F34: Conector de riel | G34: N/E | H34: 21626 | I34: LENC | J34: 24 | K34: I 0996 | L34: 1 | M34: C 1209
D35: 45580 | E35: Intertek | F35: Conector de riel | G35: N/E | H35: 21635 | I35: LENC | J35: 24 | K35: N/E | L35: 1 | M35: N/E
D36: 45580 | E36: Intertek | F36: Conector de riel | G36: N/E | H36: 21636 | I36: LENC | J36: 24 | K36: N/E | L36: 1 | M36: N/E
D37: 45580 | E37: Intertek | F37: Conector de riel | G37: N/E | H37: 21632 | I37: LENC | J37: 24 | K37: N/E | L37: 1 | M37: N/E
D38: 45580 | E38: Intertek | F38: Conector de riel | G38: N/E | H38: 21631 | I38: LENC | J38: 24 | K38: N/E | L38: 1 | M38: N/E
D39: 45580 | E39: Intertek | F39: Conector de riel | G39: N/E | H39: 21634 | I39: LENC | J39: 24 | K39: N/E | L39: 1 | M39: N/E
D40: 45580 | E40: Intertek | F40: Conector de riel | G40: N/E | H40: 21637 | I40: LENC | J40: 24 | K40: N/E | L40: 1 | M40: N/E
D41: 45580 | E41: Intertek | F41: Conector de riel | G41: N/E | H41: 21638 | I41: LENC | J41: 24 | K41: N/E | L41: 1 | M41: N/E
D42: 45580 | E42: Intertek | F42: Conector de riel | G42: N/E | H42: 21630 | I42: LENC | J42: 24 | K42: N/E | L42: 1 | M42: N/E
D43: 45467 | E43: Intertek | F43: Luminaria decorativa | G43: Ikea | H43: N/E | I43: LENC | J43: 24 | K43: I 0579 | L43: 1 | M43: C 0715
D44: 45608 | E44: Intertek | F44: Luminaria de emergencia | G44: Segurimax | H44: 21785 | I44: LENC | J44: 24 | K44: I 1086 | L44: 1 | M44: C 1302
D45: 45608 | E45: Intertek | F45: Luminaria de emergencia | G45: Segurimax | H45: 21786 | I45: LENC | J45: 24 | K45: I 1086 | L45: 1 | M45: C 1302
D46: 45608 | E46: Intertek | F46: Luminaria de emergencia | G46: Segurimax | H46: 21782 | I46: LENC | J46: 24 | K46: I 1086 | L46: 1 | M46: C 1302
D47: 45608 | E47: Intertek | F47: Luminaria de emergencia | G47: Segurimax | H47: 21783 | I47: LENC | J47: 24 | K47: I 1086 | L47: 1 | M47: C 1302
D48: Muestras custodia
D52: 45727 | E52: INTERTEK | F52: Muestras de polo reconectador | G52: N/E | H52: N/E | I52: LENC | J52: 25 | K52: N/E | L52: 1 | M52: N/E
D53: 45608 | E53: Intertek | F53: Señal de salida de emergencia | G53: Segurimax | H53: 21781 | I53: LENC | J53: 24 | K53: N/E | L53: 1 | M53: N/E
D54: 45608 | E54: Intertek | F54: Luminaria de emergencia | G54: Segurimax | H54: 21784 | I54: LENC | J54: 24 | K54: N/E | L54: 1 | M54: N/E

Sheet CONTROL_MUESTRAS_2026
D1: CONTROL DE MUESTRAS
D4: =TODAY() -> 46217 | P4: F3T09-03
A5: ÍTEM | B5: FECHA DE INGRESO | C5: NOMBRE DEL CLIENTE | D5: DESCRIPCIÓN MUESTRA | E5: MARCA | F5: REFERENCIA / MODELO | G5: REFERENCIA EXTERNA | H5: IDENTIFICACIÓN INTERNA | I5: IDENTIFICACIÓN DE MUESTRA | N5: UBICACIÓN | O5: ESTADO | P5: OBSERVACIONES
B6: AAAA-MM-DD | I6: ID | J6: AÑO | K6: INFORME | L6: N° | M6: COTIZACIÓN | N6: ESTANTE O REMISIÓN DE ENVIO
A7: ÍTEM | B7: FECHA | D7: DESCRIPCIÓN | G7: 90' | I7: 2 | J7: AÑO | K7: CONSECUTIVO | L7: Columna1 | M7: COTIZACIÓN | N7: UBICACIÓN | O7: ESTADO | P7: Columna15
A8: =IF(B8="","",COUNTA($B$7:B7)) -> 1 | B8: 46029 | C8: Cidet | D8: Sala eléctrica | E8: GIM INGENIERIA Y PROYECTOS | F8: - | G8: CP-25-407667-02 | H8: - | I8: =IF(B8="","","LENC") -> LENC | J8: =IF(B8="","",TEXT(B8,"yy")) -> 26 | K8: =IF(B8="","","N/E") -> N/E | L8: 1 | M8: =IF(D8="","","N/E") -> N/E | N8: k1 | O8: En custodia
A9: =IF(B9="","",COUNTA($B$7:B8)) -> 2 | B9: 46031 | C9: Vtek | D9: Base de lampara | E9: Tezzio | F9: - | G9: 20099 | H9: - | I9: =IF(B9="","","LENC") -> LENC | J9: =IF(B9="","",TEXT(B9,"yy")) -> 26 | K9: N/E | L9: 1 | M9: N/E | N9: H1 | O9: Almacenado
A10: =IF(B10="","",COUNTA($B$7:B9)) -> 3 | B10: 46031 | C10: Vtek | D10: Tomacorriente GFCI | E10: SIELU | F10: - | G10: 20106/20107/20108 | H10: - | I10: =IF(B10="","","LENC") -> LENC | J10: =IF(B10="","",TEXT(B10,"yy")) -> 26 | K10: I 0335 | L10: 3 | M10: C 0287 | N10: F5 | O10: Almacenado
A11: =IF(B11="","",COUNTA($B$7:B10)) -> 4 | B11: 46031 | C11: Vtek | D11: Tomacorriente | E11: SIELU | F11: - | G11: 20105/20104/20103 | H11: - | I11: =IF(B11="","","LENC") -> LENC | J11: =IF(B11="","",TEXT(B11,"yy")) -> 26 | K11: N/E | L11: 3 | M11: N/E | N11: F5 | O11: Almacenado
A12: =IF(B12="","",COUNTA($B$7:B11)) -> 5 | B12: 46031 | C12: Vtek | D12: Interruptor | E12: SIELU | F12: - | G12: 20101/20100/20102 | H12: - | I12: =IF(B12="","","LENC") -> LENC | J12: =IF(B12="","",TEXT(B12,"yy")) -> 26 | K12: N/E | L12: 3 | M12: N/E | N12: D2 | O12: En custodia
A13: =IF(B13="","",COUNTA($B$7:B12)) -> 6 | B13: 46035 | C13: Lenor | D13: Base para fotocelda | E13: MERCURY | F13: - | G13: A-7522-2025 | H13: - | I13: =IF(B13="","","LENC") -> LENC | J13: =IF(B13="","",TEXT(B13,"yy")) -> 26 | K13: I A- 7522-2025-18876 | L13: 1 | M13: N/E | N13: G5 | O13: Almacenado | P13: Está
A14: =IF(B14="","",COUNTA($B$7:B13)) -> 7 | B14: 46035 | C14: LUMECK | D14: Luminaria lineal | E14: ILUMEC | F14: - | G14: NLLHC | H14: - | I14: =IF(B14="","","LENC") -> LENC | J14: =IF(B14="","",TEXT(B14,"yy")) -> 26 | K14: N/E | L14: 1 | M14: N/E | N14: D3 | O14: En custodia
A15: =IF(B15="","",COUNTA($B$7:B14)) -> 8 | B15: 46035 | C15: NYCE | D15: Cable AWG12 | E15: Tecnolite | F15: - | G15: 20832 | H15: - | I15: =IF(B15="","","LENC") -> LENC | J15: =IF(B15="","",TEXT(B15,"yy")) -> 26 | K15: N/E | L15: 1 | M15: N/E | N15: Z1 | O15: En custodia
A16: =IF(B16="","",COUNTA($B$7:B15)) -> 9 | B16: 46035 | C16: Cidet | D16: Envolvente | E16: Legrand | F16: - | G16: 1IMB/1PER | H16: - | I16: =IF(B16="","","LENC") -> LENC | J16: =IF(B16="","",TEXT(B16,"yy")) -> 26 | K16: I 0243 | L16: 1 | M16: C 0215 | N16: 19 | O16: Enviado
A17: =IF(B17="","",COUNTA($B$7:B16)) -> 10 | B17: 46037 | C17: NYCE | D17: Bombillo LED | E17: KARLUZ | F17: - | G17: N/E | H17: - | I17: =IF(B17="","","LENC") -> LENC | J17: =IF(B17="","",TEXT(B17,"yy")) -> 26 | K17: N/E | L17: 2 | M17: N/E | N17: Z1 | O17: En custodia
A18: =IF(B18="","",COUNTA($B$7:B17)) -> 11 | B18: 46037 | C18: NYCE | D18: Extensión | E18: GLOBY | F18: - | G18: N/E | H18: - | I18: =IF(B18="","","LENC") -> LENC | J18: =IF(B18="","",TEXT(B18,"yy")) -> 26 | K18: N/E | L18: 2 | M18: N/E | N18: Z1 | O18: En custodia
A19: =IF(B19="","",COUNTA($B$7:B18)) -> 12 | B19: 46038 | C19: NYCE | D19: Cajas de paso | E19: DURMAN | F19: - | G19: N/E | H19: - | I19: =IF(B19="","","LENC") -> LENC | J19: =IF(B19="","",TEXT(B19,"yy")) -> 26 | K19: N/E | L19: 6 | M19: N/E | N19: Z2 | O19: En custodia
A20: =IF(B20="","",COUNTA($B$7:B19)) -> 13 | B20: 46038 | C20: Lenor | D20: Luminaria de alumbrado publico | E20: FONROCHE LIGTHING | F20: - | G20: A-7377-2025-19072 | H20: - | I20: =IF(B20="","","LENC") -> LENC | J20: =IF(B20="","",TEXT(B20,"yy")) -> 26 | K20: I 0088 / 0089 | L20: 1 | M20: C 0077 | N20: D3 | O20: En curso
A21: =IF(B21="","",COUNTA($B$7:B20)) -> 14 | B21: 46038 | C21: Lenor | D21: Luminaria de alumbrado publico | E21: GDS | F21: - | G21: A-7456-2025-RP-32 | H21: - | I21: =IF(B21="","","LENC") -> LENC | J21: =IF(B21="","",TEXT(B21,"yy")) -> 26 | K21: I 0052 / I 0057 | L21: 1 | M21: N/E | N21: H7 | O21: Almacenado | P21: Está
A22: =IF(B22="","",COUNTA($B$7:B21)) -> 15 | B22: 46038 | C22: NYCE | D22: Base de estufa | E22: LCI | F22: - | G22: N/E | H22: - | I22: =IF(B22="","","LENC") -> LENC | J22: =IF(B22="","",TEXT(B22,"yy")) -> 26 | K22: I 1247 | L22: 2 | M22: C 0924 | N22: D3 | O22: En curso
A23: =IF(B23="","",COUNTA($B$7:B22)) -> 16 | B23: 46041 | C23: Whirlpool | D23: Lavadoras | E23: Whirlpool | F23: - | G23: N/E | H23: - | I23: =IF(B23="","","LENC") -> LENC | J23: =IF(B23="","",TEXT(B23,"yy")) -> 26 | K23: N/E | L23: 6 | M23: N/E | N23: 33 | O23: Enviado | P23: Recogido por Cliente
A24: =IF(B24="","",COUNTA($B$7:B23)) -> 17 | B24: 46013 | C24: Cidet | D24: Cables | E24: N/E | F24: - | G24: 25149 / 25138 | H24: - | I24: =IF(B24="","","LENC") -> LENC | J24: =IF(B24="","",TEXT(B24,"yy")) -> 25 | K24: I 0014 | L24: 2 | M24: C 0024 | N24: Z1 | O24: En custodia
A25: =IF(B25="","",COUNTA($B$7:B24)) -> 18 | B25: 46029 | C25: Cidet | D25: Encerramiento metálico | E25: Gim | F25: - | G25: CP25-407667-01 | H25: - | I25: =IF(B25="","","LENC") -> LENC | J25: =IF(B25="","",TEXT(B25,"yy")) -> 26 | K25: I 1266 | L25: 1 | M25: C 1224 | N25: 10 | O25: Enviado
A26: =IF(B26="","",COUNTA($B$7:B25)) -> 19 | B26: 46046 | C26: NYCE / ELECTRICOS DEL RUIZ | D26: Bombillos G45 | E26: KARLUZ | F26: - | G26: 12535 / 12536 | H26: - | I26: =IF(B26="","","LENC") -> LENC | J26: =IF(B26="","",TEXT(B26,"yy")) -> 26 | K26: I 0172 | L26: 2 | M26: C 0170 | N26: Steven | O26: En curso
A27: =IF(B27="","",COUNTA($B$7:B26)) -> 20 | B27: 46048 | C27: Incoltapas | D27: Fondos y chapolas | E27: Incoltapas | F27: - | G27: Varias | H27: - | I27: =IF(B27="","","LENC") -> LENC | J27: =IF(B27="","",TEXT(B27,"yy")) -> 26 | K27: N/E | L27: 10 | M27: N/E | N27: Z1 | O27: En custodia
A28: =IF(B28="","",COUNTA($B$7:B27)) -> 21 | B28: 46052 | C28: NYCE | D28: Transformador 150 KVA | F28: - | G28: N/E | H28: - | I28: =IF(B28="","","LENC") -> LENC | J28: =IF(B28="","",TEXT(B28,"yy")) -> 26 | K28: N/E | L28: 1 | M28: N/E | N28: K1 | O28: En custodia
A29: =IF(B29="","",COUNTA($B$7:B28)) -> 22 | B29: 46052 | C29: SGS | D29: Encerramiento metálico | E29: CDM TRANSFORMADORES | F29: - | G29: N/E | H29: - | I29: =IF(B29="","","LENC") -> LENC | J29: =IF(B29="","",TEXT(B29,"yy")) -> 26 | K29: I 0188 / 0189 | L29: 1 | M29: C 1134 | N29: 69 | O29: Enviado
A30: =IF(B30="","",COUNTA($B$7:B29)) -> 23 | B30: 46051 | C30: Certecnica | D30: Probetas metalicas | E30: N/E | F30: - | G30: 01322 - 01323 - 01324 - 01325 | H30: - | I30: =IF(B30="","","LENC") -> LENC | J30: =IF(B30="","",TEXT(B30,"yy")) -> 26 | K30: N/E | L30: 1 | M30: N/E | N30: Z2 | O30: En custodia
A31: =IF(B31="","",COUNTA($B$7:B30)) -> 24 | B31: 46051 | C31: NYCE | D31: Protector de voltaje | E31: Forza | F31: - | G31: N/E | H31: - | I31: =IF(B31="","","LENC") -> LENC | J31: =IF(B31="","",TEXT(B31,"yy")) -> 26 | K31: I 0225 | L31: 6 | M31: C 0154 | N31: H5 | O31: Almacenado | P31: Está
A32: =IF(B32="","",COUNTA($B$7:B31)) -> 25 | B32: 46051 | C32: Meico | D32: Bombillo 100W | E32: FullWat | F32: - | G32: N/E | H32: - | I32: =IF(B32="","","LENC") -> LENC | J32: =IF(B32="","",TEXT(B32,"yy")) -> 26 | K32: I 0175 | L32: 4 | M32: C 0085 | N32: 38 | O32: Enviado | P32: Recogido por cliente
A33: =IF(B33="","",COUNTA($B$7:B32)) -> 26 | B33: 46051 | C33: Meico | D33: Bombillo 40W | E33: FullWat | F33: - | G33: N/E | H33: - | I33: =IF(B33="","","LENC") -> LENC | J33: =IF(B33="","",TEXT(B33,"yy")) -> 26 | K33: I 0175 | L33: 2 | M33: C 0085 | N33: 38 | O33: Enviado | P33: Recogido por cliente
A34: =IF(B34="","",COUNTA($B$7:B33)) -> 27 | B34: 46050 | C34: SELDA1 | D34: Breaker 100A | E34: Blox | F34: - | G34: 18879 | H34: - | I34: =IF(B34="","","LENC") -> LENC | J34: =IF(B34="","",TEXT(B34,"yy")) -> 26 | K34: I 0325 | L34: 1 | M34: C 0247 | N34: B3 | O34: Almacenado
A35: =IF(B35="","",COUNTA($B$7:B34)) -> 28 | B35: 46050 | C35: SELDA1 | D35: Contactor 80A | E35: Blox | F35: - | G35: 18880 | H35: - | I35: =IF(B35="","","LENC") -> LENC | J35: =IF(B35="","",TEXT(B35,"yy")) -> 26 | K35: I 0325 | L35: 1 | M35: C 0247 | N35: B3 | O35: Almacenado
A36: =IF(B36="","",COUNTA($B$7:B35)) -> 29 | B36: 46050 | C36: SELDA1 | D36: Contactor 32A | E36: Blox | F36: - | G36: 18878 | H36: - | I36: =IF(B36="","","LENC") -> LENC | J36: =IF(B36="","",TEXT(B36,"yy")) -> 26 | K36: I 0325 | L36: 1 | M36: C 0247 | N36: B3 | O36: Almacenado
A37: =IF(B37="","",COUNTA($B$7:B36)) -> 30 | B37: 46050 | C37: SELDA1 | D37: Conector industrial 125A | E37: Blox | F37: - | G37: 18883 | H37: - | I37: =IF(B37="","","LENC") -> LENC | J37: =IF(B37="","",TEXT(B37,"yy")) -> 26 | K37: I 0325 | L37: 1 | M37: C 0247 | N37: B3 | O37: Almacenado
A38: =IF(B38="","",COUNTA($B$7:B37)) -> 31 | B38: 46050 | C38: SELDA1 | D38: Conector industrial 63A | E38: Blox | F38: - | G38: 18884 | H38: - | I38: =IF(B38="","","LENC") -> LENC | J38: =IF(B38="","",TEXT(B38,"yy")) -> 26 | K38: I 0325 | L38: 1 | M38: C 0247 | N38: B3 | O38: Almacenado
A39: =IF(B39="","",COUNTA($B$7:B38)) -> 32 | B39: 46050 | C39: SELDA1 | D39: Conector industrial 32A | E39: Blox | F39: - | G39: 18882 | H39: - | I39: =IF(B39="","","LENC") -> LENC | J39: =IF(B39="","",TEXT(B39,"yy")) -> 26 | K39: I 0325 | L39: 1 | M39: C 0247 | N39: B3 | O39: Almacenado
A40: =IF(B40="","",COUNTA($B$7:B39)) -> 33 | B40: 46050 | C40: SELDA1 | D40: Conector industrial 16A | E40: Blox | F40: - | G40: 18881 | H40: - | I40: =IF(B40="","","LENC") -> LENC | J40: =IF(B40="","",TEXT(B40,"yy")) -> 26 | K40: I 0325 | L40: 1 | M40: C 0247 | N40: 27 | O40: Laboratorio Externo
A41: =IF(B41="","",COUNTA($B$7:B40)) -> 34 | B41: 46050 | C41: SELDA1 | D41: Breaker C40 | E41: Blox | F41: - | G41: 18885 | H41: - | I41: =IF(B41="","","LENC") -> LENC | J41: =IF(B41="","",TEXT(B41,"yy")) -> 26 | K41: N/E | L41: 1 | M41: N/E | N41: Steven | O41: En curso
A42: =IF(B42="","",COUNTA($B$7:B41)) -> 35 | B42: 46051 | C42: NYCE | D42: Conector | E42: Finder | F42: - | G42: 20859 | H42: - | I42: =IF(B42="","","LENC") -> LENC | J42: =IF(B42="","",TEXT(B42,"yy")) -> 26 | K42: I 0231 | L42: 1 | M42: N/E | N42: E3 | O42: Almacenado
...

Sheet REMISIÓN 2026
A2: REMISIÓN DE MUESTRAS
K3: F9T09-02
F4: FECHA DE ELABORACIÓN | G4: =TODAY() -> 46217 | I4: CONSECUTIVO | J4: 109
B7: LABORATORIO DE ENSAYOS NYCE COLOMBIA S.A.S | N7: 0
B9: CLIENTE | D9: =IF(M12>0,(UPPER(_xlfn.XLOOKUP(M12,CONTROL_MUESTRAS_2026!A:A,CONTROL_MUESTRAS_2026!C:C,"No encontrado",0))),"") -> NICOMAR ELECTRONICS | G9: TIPO DE SALIDA | I9: Solicitado por personal de Nyce
B11: IDENTIFICACIÓN INTERNA | D11: IDENTIFICACIÓN EXTERNA | E11: DESCRIPCIÓN | G11: FABRICANTE /MARCA | H11: OBSERVACIONES | J11: FECHA DE RECEPCIÓN | K11: FECHA DE ENTREGA | M11: PEGAR AQUÍ ÍTEM ︾
B12: {=IF(M12>0,(UPPER(_xlfn.XLOOKUP(M12,CONTROL_MUESTRAS_2026!A:A,CONCATENATE(CONTROL_MUESTRAS_2026!I:I," - ",CONTROL_MUESTRAS_2026!J:J," - ",CONTROL_MUESTRAS_2026!K:K),"No encontrado",0))),"")} -> LENC - 26 - N/E | D12: =IF(M12>0,(UPPER(_xlfn.XLOOKUP(M12,CONTROL_MUESTRAS_2026!A:A,CONTROL_MUESTRAS_2026!G:G,"No encontrado",0))),"") -> 21714 | E12: =IF(M12>0,(UPPER(_xlfn.XLOOKUP(M12,CONTROL_MUESTRAS_2026!A:A,CONTROL_MUESTRAS_2026!D:D,"No encontrado",0))),"") -> MULTITOMA FIJA | G12: =IF(M12>0,(UPPER(_xlfn.XLOOKUP(M12,CONTROL_MUESTRAS_2026!A:A,CONTROL_MUESTRAS_2026!E:E,"No encontrado",0))),"") -> POWEST | H12: Ninguna | J12: =IF(M12>0,TEXT(_xlfn.XLOOKUP(M12,CONTROL_MUESTRAS_2026!A:A,CONTROL_MUESTRAS_2026!B:B,"No encontrado",0),"yyyy-mm-dd"),"") -> 2026-06-18 | K12: =$G$4 -> 46217 | M12: 745 | P12: Soloicitado por personal de producto
B13: {=IF(M13>0,(UPPER(_xlfn.XLOOKUP(M13,CONTROL_MUESTRAS_2026!A:A,CONCATENATE(CONTROL_MUESTRAS_2026!I:I," - ",CONTROL_MUESTRAS_2026!J:J," - ",CONTROL_MUESTRAS_2026!K:K),"No encontrado",0))),"")} | D13: =IF(M13>0,(UPPER(_xlfn.XLOOKUP(M13,CONTROL_MUESTRAS_2026!A:A,CONTROL_MUESTRAS_2026!G:G,"No encontrado",0))),"") | E13: =IF(M13>0,(UPPER(_xlfn.XLOOKUP(M13,CONTROL_MUESTRAS_2026!A:A,CONTROL_MUESTRAS_2026!D:D,"No encontrado",0))),"") | G13: =IF(M13>0,(UPPER(_xlfn.XLOOKUP(M13,CONTROL_MUESTRAS_2026!A:A,CONTROL_MUESTRAS_2026!E:E,"No encontrado",0))),"") | H13: Ninguna | J13: =IF(M13>0,TEXT(_xlfn.XLOOKUP(M13,CONTROL_MUESTRAS_2026!A:A,CONTROL_MUESTRAS_2026!B:B,"No encontrado",0),"yyyy-mm-dd"),"") | K13: =$G$4 -> 46217 | P13: Laboratorio externo
B14: {=IF(M14>0,(UPPER(_xlfn.XLOOKUP(M14,CONTROL_MUESTRAS_2026!A:A,CONCATENATE(CONTROL_MUESTRAS_2026!I:I," - ",CONTROL_MUESTRAS_2026!J:J," - ",CONTROL_MUESTRAS_2026!K:K),"No encontrado",0))),"")} | D14: =IF(M14>0,(UPPER(_xlfn.XLOOKUP(M14,CONTROL_MUESTRAS_2026!A:A,CONTROL_MUESTRAS_2026!G:G,"No encontrado",0))),"") | E14: =IF(M14>0,(UPPER(_xlfn.XLOOKUP(M14,CONTROL_MUESTRAS_2026!A:A,CONTROL_MUESTRAS_2026!D:D,"No encontrado",0))),"") | G14: =IF(M14>0,(UPPER(_xlfn.XLOOKUP(M14,CONTROL_MUESTRAS_2026!A:A,CONTROL_MUESTRAS_2026!E:E,"No encontrado",0))),"") | H14: Ninguna | J14: =IF(M14>0,TEXT(_xlfn.XLOOKUP(M14,CONTROL_MUESTRAS_2026!A:A,CONTROL_MUESTRAS_2026!B:B,"No encontrado",0),"yyyy-mm-dd"),"") | K14: =$G$4 -> 46217 | P14: Recogido por el cliente
B15: {=IF(M15>0,(UPPER(_xlfn.XLOOKUP(M15,CONTROL_MUESTRAS_2026!A:A,CONCATENATE(CONTROL_MUESTRAS_2026!I:I," - ",CONTROL_MUESTRAS_2026!J:J," - ",CONTROL_MUESTRAS_2026!K:K),"No encontrado",0))),"")} | D15: =IF(M15>0,(UPPER(_xlfn.XLOOKUP(M15,CONTROL_MUESTRAS_2026!A:A,CONTROL_MUESTRAS_2026!G:G,"No encontrado",0))),"") | E15: =IF(M15>0,(UPPER(_xlfn.XLOOKUP(M15,CONTROL_MUESTRAS_2026!A:A,CONTROL_MUESTRAS_2026!D:D,"No encontrado",0))),"") | G15: =IF(M15>0,(UPPER(_xlfn.XLOOKUP(M15,CONTROL_MUESTRAS_2026!A:A,CONTROL_MUESTRAS_2026!E:E,"No encontrado",0))),"") | H15: Ninguna | J15: =IF(M15>0,TEXT(_xlfn.XLOOKUP(M15,CONTROL_MUESTRAS_2026!A:A,CONTROL_MUESTRAS_2026!B:B,"No encontrado",0),"yyyy-mm-dd"),"") | K15: =$G$4 -> 46217 | P15: Enviado por transportadora
B16: {=IF(M16>0,(UPPER(_xlfn.XLOOKUP(M16,CONTROL_MUESTRAS_2026!A:A,CONCATENATE(CONTROL_MUESTRAS_2026!I:I," - ",CONTROL_MUESTRAS_2026!J:J," - ",CONTROL_MUESTRAS_2026!K:K),"No encontrado",0))),"")} | D16: =IF(M16>0,(UPPER(_xlfn.XLOOKUP(M16,CONTROL_MUESTRAS_2026!A:A,CONTROL_MUESTRAS_2026!G:G,"No encontrado",0))),"") | E16: =IF(M16>0,(UPPER(_xlfn.XLOOKUP(M16,CONTROL_MUESTRAS_2026!A:A,CONTROL_MUESTRAS_2026!D:D,"No encontrado",0))),"") | G16: =IF(M16>0,(UPPER(_xlfn.XLOOKUP(M16,CONTROL_MUESTRAS_2026!A:A,CONTROL_MUESTRAS_2026!E:E,"No encontrado",0))),"") | H16: Ninguna | J16: =IF(M16>0,TEXT(_xlfn.XLOOKUP(M16,CONTROL_MUESTRAS_2026!A:A,CONTROL_MUESTRAS_2026!B:B,"No encontrado",0),"yyyy-mm-dd"),"") | K16: =$G$4 -> 46217
B17: {=IF(M17>0,(UPPER(_xlfn.XLOOKUP(M17,CONTROL_MUESTRAS_2026!A:A,CONCATENATE(CONTROL_MUESTRAS_2026!I:I," - ",CONTROL_MUESTRAS_2026!J:J," - ",CONTROL_MUESTRAS_2026!K:K),"No encontrado",0))),"")} | D17: =IF(M17>0,(UPPER(_xlfn.XLOOKUP(M17,CONTROL_MUESTRAS_2026!A:A,CONTROL_MUESTRAS_2026!G:G,"No encontrado",0))),"") | E17: =IF(M17>0,(UPPER(_xlfn.XLOOKUP(M17,CONTROL_MUESTRAS_2026!A:A,CONTROL_MUESTRAS_2026!D:D,"No encontrado",0))),"") | G17: =IF(M17>0,(UPPER(_xlfn.XLOOKUP(M17,CONTROL_MUESTRAS_2026!A:A,CONTROL_MUESTRAS_2026!E:E,"No encontrado",0))),"") | H17: Ninguna | J17: =IF(M17>0,TEXT(_xlfn.XLOOKUP(M17,CONTROL_MUESTRAS_2026!A:A,CONTROL_MUESTRAS_2026!B:B,"No encontrado",0),"yyyy-mm-dd"),"") | K17: =$G$4 -> 46217
B18: {=IF(M18>0,(UPPER(_xlfn.XLOOKUP(M18,CONTROL_MUESTRAS_2026!A:A,CONCATENATE(CONTROL_MUESTRAS_2026!I:I," - ",CONTROL_MUESTRAS_2026!J:J," - ",CONTROL_MUESTRAS_2026!K:K),"No encontrado",0))),"")} | D18: =IF(M18>0,(UPPER(_xlfn.XLOOKUP(M18,CONTROL_MUESTRAS_2026!A:A,CONTROL_MUESTRAS_2026!G:G,"No encontrado",0))),"") | E18: =IF(M18>0,(UPPER(_xlfn.XLOOKUP(M18,CONTROL_MUESTRAS_2026!A:A,CONTROL_MUESTRAS_2026!D:D,"No encontrado",0))),"") | G18: =IF(M18>0,(UPPER(_xlfn.XLOOKUP(M18,CONTROL_MUESTRAS_2026!A:A,CONTROL_MUESTRAS_2026!E:E,"No encontrado",0))),"") | H18: Ninguna | J18: =IF(M18>0,TEXT(_xlfn.XLOOKUP(M18,CONTROL_MUESTRAS_2026!A:A,CONTROL_MUESTRAS_2026!B:B,"No encontrado",0),"yyyy-mm-dd"),"") | K18: =$G$4 -> 46217
B19: {=IF(M19>0,(UPPER(_xlfn.XLOOKUP(M19,CONTROL_MUESTRAS_2026!A:A,CONCATENATE(CONTROL_MUESTRAS_2026!I:I," - ",CONTROL_MUESTRAS_2026!J:J," - ",CONTROL_MUESTRAS_2026!K:K),"No encontrado",0))),"")} | D19: =IF(M19>0,(UPPER(_xlfn.XLOOKUP(M19,CONTROL_MUESTRAS_2026!A:A,CONTROL_MUESTRAS_2026!G:G,"No encontrado",0))),"") | E19: =IF(M19>0,(UPPER(_xlfn.XLOOKUP(M19,CONTROL_MUESTRAS_2026!A:A,CONTROL_MUESTRAS_2026!D:D,"No encontrado",0))),"") | G19: =IF(M19>0,(UPPER(_xlfn.XLOOKUP(M19,CONTROL_MUESTRAS_2026!A:A,CONTROL_MUESTRAS_2026!E:E,"No encontrado",0))),"") | H19: Ninguna | J19: =IF(M19>0,TEXT(_xlfn.XLOOKUP(M19,CONTROL_MUESTRAS_2026!A:A,CONTROL_MUESTRAS_2026!B:B,"No encontrado",0),"yyyy-mm-dd"),"") | K19: =$G$4 -> 46217
B20: {=IF(M20>0,(UPPER(_xlfn.XLOOKUP(M20,CONTROL_MUESTRAS_2026!A:A,CONCATENATE(CONTROL_MUESTRAS_2026!I:I," - ",CONTROL_MUESTRAS_2026!J:J," - ",CONTROL_MUESTRAS_2026!K:K),"No encontrado",0))),"")} | D20: =IF(M20>0,(UPPER(_xlfn.XLOOKUP(M20,CONTROL_MUESTRAS_2026!A:A,CONTROL_MUESTRAS_2026!G:G,"No encontrado",0))),"") | E20: =IF(M20>0,(UPPER(_xlfn.XLOOKUP(M20,CONTROL_MUESTRAS_2026!A:A,CONTROL_MUESTRAS_2026!D:D,"No encontrado",0))),"") | G20: =IF(M20>0,(UPPER(_xlfn.XLOOKUP(M20,CONTROL_MUESTRAS_2026!A:A,CONTROL_MUESTRAS_2026!E:E,"No encontrado",0))),"") | H20: Ninguna | J20: =IF(M20>0,TEXT(_xlfn.XLOOKUP(M20,CONTROL_MUESTRAS_2026!A:A,CONTROL_MUESTRAS_2026!B:B,"No encontrado",0),"yyyy-mm-dd"),"") | K20: =$G$4 -> 46217
B21: {=IF(M21>0,(UPPER(_xlfn.XLOOKUP(M21,CONTROL_MUESTRAS_2026!A:A,CONCATENATE(CONTROL_MUESTRAS_2026!I:I," - ",CONTROL_MUESTRAS_2026!J:J," - ",CONTROL_MUESTRAS_2026!K:K),"No encontrado",0))),"")} | D21: =IF(M21>0,(UPPER(_xlfn.XLOOKUP(M21,CONTROL_MUESTRAS_2026!A:A,CONTROL_MUESTRAS_2026!G:G,"No encontrado",0))),"") | E21: =IF(M21>0,(UPPER(_xlfn.XLOOKUP(M21,CONTROL_MUESTRAS_2026!A:A,CONTROL_MUESTRAS_2026!D:D,"No encontrado",0))),"") | G21: =IF(M21>0,(UPPER(_xlfn.XLOOKUP(M21,CONTROL_MUESTRAS_2026!A:A,CONTROL_MUESTRAS_2026!E:E,"No encontrado",0))),"") | H21: Ninguna | J21: =IF(M21>0,TEXT(_xlfn.XLOOKUP(M21,CONTROL_MUESTRAS_2026!A:A,CONTROL_MUESTRAS_2026!B:B,"No encontrado",0),"yyyy-mm-dd"),"") | K21: =$G$4 -> 46217
B22: {=IF(M22>0,(UPPER(_xlfn.XLOOKUP(M22,CONTROL_MUESTRAS_2026!A:A,CONCATENATE(CONTROL_MUESTRAS_2026!I:I," - ",CONTROL_MUESTRAS_2026!J:J," - ",CONTROL_MUESTRAS_2026!K:K),"No encontrado",0))),"")} | D22: =IF(M22>0,(UPPER(_xlfn.XLOOKUP(M22,CONTROL_MUESTRAS_2026!A:A,CONTROL_MUESTRAS_2026!G:G,"No encontrado",0))),"") | E22: =IF(M22>0,(UPPER(_xlfn.XLOOKUP(M22,CONTROL_MUESTRAS_2026!A:A,CONTROL_MUESTRAS_2026!D:D,"No encontrado",0))),"") | G22: =IF(M22>0,(UPPER(_xlfn.XLOOKUP(M22,CONTROL_MUESTRAS_2026!A:A,CONTROL_MUESTRAS_2026!E:E,"No encontrado",0))),"") | H22: Ninguna | J22: =IF(M22>0,TEXT(_xlfn.XLOOKUP(M22,CONTROL_MUESTRAS_2026!A:A,CONTROL_MUESTRAS_2026!B:B,"No encontrado",0),"yyyy-mm-dd"),"") | K22: =$G$4 -> 46217
B23: {=IF(M23>0,(UPPER(_xlfn.XLOOKUP(M23,CONTROL_MUESTRAS_2026!A:A,CONCATENATE(CONTROL_MUESTRAS_2026!I:I," - ",CONTROL_MUESTRAS_2026!J:J," - ",CONTROL_MUESTRAS_2026!K:K),"No encontrado",0))),"")} | D23: =IF(M23>0,(UPPER(_xlfn.XLOOKUP(M23,CONTROL_MUESTRAS_2026!A:A,CONTROL_MUESTRAS_2026!G:G,"No encontrado",0))),"") | E23: =IF(M23>0,(UPPER(_xlfn.XLOOKUP(M23,CONTROL_MUESTRAS_2026!A:A,CONTROL_MUESTRAS_2026!D:D,"No encontrado",0))),"") | G23: =IF(M23>0,(UPPER(_xlfn.XLOOKUP(M23,CONTROL_MUESTRAS_2026!A:A,CONTROL_MUESTRAS_2026!E:E,"No encontrado",0))),"") | H23: Ninguna | J23: =IF(M23>0,TEXT(_xlfn.XLOOKUP(M23,CONTROL_MUESTRAS_2026!A:A,CONTROL_MUESTRAS_2026!B:B,"No encontrado",0),"yyyy-mm-dd"),"") | K23: =$G$4 -> 46217
B24: {=IF(M24>0,(UPPER(_xlfn.XLOOKUP(M24,CONTROL_MUESTRAS_2026!A:A,CONCATENATE(CONTROL_MUESTRAS_2026!I:I," - ",CONTROL_MUESTRAS_2026!J:J," - ",CONTROL_MUESTRAS_2026!K:K),"No encontrado",0))),"")} | D24: =IF(M24>0,(UPPER(_xlfn.XLOOKUP(M24,CONTROL_MUESTRAS_2026!A:A,CONTROL_MUESTRAS_2026!G:G,"No encontrado",0))),"") | E24: =IF(M24>0,(UPPER(_xlfn.XLOOKUP(M24,CONTROL_MUESTRAS_2026!A:A,CONTROL_MUESTRAS_2026!D:D,"No encontrado",0))),"") | G24: =IF(M24>0,(UPPER(_xlfn.XLOOKUP(M24,CONTROL_MUESTRAS_2026!A:A,CONTROL_MUESTRAS_2026!E:E,"No encontrado",0))),"") | H24: Ninguna | J24: =IF(M24>0,TEXT(_xlfn.XLOOKUP(M24,CONTROL_MUESTRAS_2026!A:A,CONTROL_MUESTRAS_2026!B:B,"No encontrado",0),"yyyy-mm-dd"),"") | K24: =$G$4 -> 46217
B25: {=IF(M25>0,(UPPER(_xlfn.XLOOKUP(M25,CONTROL_MUESTRAS_2026!A:A,CONCATENATE(CONTROL_MUESTRAS_2026!I:I," - ",CONTROL_MUESTRAS_2026!J:J," - ",CONTROL_MUESTRAS_2026!K:K),"No encontrado",0))),"")} | D25: =IF(M25>0,(UPPER(_xlfn.XLOOKUP(M25,CONTROL_MUESTRAS_2026!A:A,CONTROL_MUESTRAS_2026!G:G,"No encontrado",0))),"") | E25: =IF(M25>0,(UPPER(_xlfn.XLOOKUP(M25,CONTROL_MUESTRAS_2026!A:A,CONTROL_MUESTRAS_2026!D:D,"No encontrado",0))),"") | G25: =IF(M25>0,(UPPER(_xlfn.XLOOKUP(M25,CONTROL_MUESTRAS_2026!A:A,CONTROL_MUESTRAS_2026!E:E,"No encontrado",0))),"") | H25: Ninguna | J25: =IF(M25>0,TEXT(_xlfn.XLOOKUP(M25,CONTROL_MUESTRAS_2026!A:A,CONTROL_MUESTRAS_2026!B:B,"No encontrado",0),"yyyy-mm-dd"),"") | K25: =$G$4 -> 46217
B26: {=IF(M26>0,(UPPER(_xlfn.XLOOKUP(M26,CONTROL_MUESTRAS_2026!A:A,CONCATENATE(CONTROL_MUESTRAS_2026!I:I," - ",CONTROL_MUESTRAS_2026!J:J," - ",CONTROL_MUESTRAS_2026!K:K),"No encontrado",0))),"")} | D26: =IF(M26>0,(UPPER(_xlfn.XLOOKUP(M26,CONTROL_MUESTRAS_2026!A:A,CONTROL_MUESTRAS_2026!G:G,"No encontrado",0))),"") | E26: =IF(M26>0,(UPPER(_xlfn.XLOOKUP(M26,CONTROL_MUESTRAS_2026!A:A,CONTROL_MUESTRAS_2026!D:D,"No encontrado",0))),"") | G26: =IF(M26>0,(UPPER(_xlfn.XLOOKUP(M26,CONTROL_MUESTRAS_2026!A:A,CONTROL_MUESTRAS_2026!E:E,"No encontrado",0))),"") | H26: Ninguna | J26: =IF(M26>0,TEXT(_xlfn.XLOOKUP(M26,CONTROL_MUESTRAS_2026!A:A,CONTROL_MUESTRAS_2026!B:B,"No encontrado",0),"yyyy-mm-dd"),"") | K26: =$G$4 -> 46217
B27: {=IF(M27>0,(UPPER(_xlfn.XLOOKUP(M27,CONTROL_MUESTRAS_2026!A:A,CONCATENATE(CONTROL_MUESTRAS_2026!I:I," - ",CONTROL_MUESTRAS_2026!J:J," - ",CONTROL_MUESTRAS_2026!K:K),"No encontrado",0))),"")} | D27: =IF(M27>0,(UPPER(_xlfn.XLOOKUP(M27,CONTROL_MUESTRAS_2026!A:A,CONTROL_MUESTRAS_2026!G:G,"No encontrado",0))),"") | E27: =IF(M27>0,(UPPER(_xlfn.XLOOKUP(M27,CONTROL_MUESTRAS_2026!A:A,CONTROL_MUESTRAS_2026!D:D,"No encontrado",0))),"") | G27: =IF(M27>0,(UPPER(_xlfn.XLOOKUP(M27,CONTROL_MUESTRAS_2026!A:A,CONTROL_MUESTRAS_2026!E:E,"No encontrado",0))),"") | H27: Ninguna | J27: =IF(M27>0,TEXT(_xlfn.XLOOKUP(M27,CONTROL_MUESTRAS_2026!A:A,CONTROL_MUESTRAS_2026!B:B,"No encontrado",0),"yyyy-mm-dd"),"") | K27: =$G$4 -> 46217
B29: TOTAL MUESTRAS | C29: {=SUMPRODUCT((D12:D27<>"")*1)} -> 1 | D29: NUMERO DE EMPAQUES | E29: 1 | F29: OBSERVACIÓN FINAL DE LAS MUESTRAS | P29: Soloicitado por personal de producto
P30: Recogido por el cliente
C32: ENTREGADO POR: | G32: ENTREGADO A: | R32: =IF(H30>0,(UPPER(_xlfn.XLOOKUP(H30,[2]CONTROL_MUESTRAS_2025!A:A,[2]CONTROL_MUESTRAS_2025!I:I,"No encontrado",0))),"")
C33: Brandon Trujillo | G33: FIRMA: | R33: =IF(M30>0,(UPPER(_xlfn.XLOOKUP(M30,[2]CONTROL_MUESTRAS_2025!A:A,[2]CONTROL_MUESTRAS_2025!I:I,"No encontrado",0))),"")
G34: CEDULA: | P34: Las muestras fueron sometidas a ensayos destructivos, por lo cual no se encuentran en buen estado. | R34: =IF(M31>0,(UPPER(_xlfn.XLOOKUP(M31,[2]CONTROL_MUESTRAS_2025!A:A,[2]CONTROL_MUESTRAS_2025!I:I,"No encontrado",0))),"")
C35: Auxiliar de laboratorio | G35: NOMBRE Y PLACA: | R35: =IF(M32>0,(UPPER(_xlfn.XLOOKUP(M32,[2]CONTROL_MUESTRAS_2025!A:A,[2]CONTROL_MUESTRAS_2025!I:I,"No encontrado",0))),"")
B37: ENTRADA EN VIGOR 2023-08-30 | R37: =IF(M33>0,(UPPER(_xlfn.XLOOKUP(M33,[2]CONTROL_MUESTRAS_2025!A:A,[2]CONTROL_MUESTRAS_2025!I:I,"No encontrado",0))),"")
B38: Se prohíbe la reproducción total o parcial sin previa autorización
B39: NYCE Colombia S.A.S. | Calle 30 No. 17 - 52 | Teusaquillo - Bogotá D.C. Colombia | Tel. + 571 756 84 85 ext. 129
R40: =IF(M37>0,(UPPER(_xlfn.XLOOKUP(M37,[2]CONTROL_MUESTRAS_2025!A:A,[2]CONTROL_MUESTRAS_2025!I:I,"No encontrado",0))),"")
A43: REMISIÓN DE MUESTRAS
K45: F9T09-02
F46: FECHA DE ELABORACIÓN | G46: =G4 -> 46217 | I46: CONSECUTIVO | J46: =J4 -> 109
B49: LABORATORIO DE ENSAYOS NYCE COLOMBIA S.A.S
B52: CLIENTE | D52: =D9 -> NICOMAR ELECTRONICS | G52: TIPO DE SALIDA | I52: =I9 -> Solicitado por personal de Nyce
B54: IDENTIFICACIÓN INTERNA | D54: IDENTIFICACIÓN EXTERNA | E54: DESCRIPCIÓN | G54: FABRICANTE /MARCA | H54: OBSERVACIONES | J54: FECHA DE RECEPCIÓN | K54: FECHA DE ENTREGA
B55: =B12 -> LENC - 26 - N/E | D55: =D12 -> 21714 | E55: =E12 -> MULTITOMA FIJA | G55: =G12 -> POWEST | H55: =H12 -> Ninguna | J55: =J12 -> 2026-06-18 | K55: =K12 -> 46217
B56: =B13 | D56: =D13 | E56: =E13 | G56: =G13 | H56: =H13 -> Ninguna | J56: =J13 | K56: =K13 -> 46217
...

Sheet REMISIÓN 2025 (2)
A2: REMISIÓN DE MUESTRAS
K3: F9T09-02
F4: FECHA DE ELABORACIÓN | G4: =TODAY() -> 46217 | I4: CONSECUTIVO | J4: 1060
B7: LABORATORIO DE ENSAYOS NYCE COLOMBIA S.A.S
B9: CLIENTE | D9: Cooper | G9: TIPO DE SALIDA | I9: RECOLECCIÓN POR PARTE DEL CLIENTE
B11: IDENTIFICACIÓN INTERNA | D11: IDENTIFICACIÓN EXTERNA | E11: DESCRIPCIÓN | G11: FABRICANTE /MARCA | H11: OBSERVACIONES | J11: FECHA DE RECEPCIÓN | K11: FECHA DE ENTREGA | M11: PEGAR AQUÍ ÍTEM ︾
B12: LENC - 25 - I 0940 | D12: =IF(M12>0,(UPPER(_xlfn.XLOOKUP(M12,#REF!,#REF!,"No encontrado",0))),"") -> #REF! | E12: =IF(M12>0,(PROPER(_xlfn.XLOOKUP(M12,#REF!,#REF!,"No encontrado",0))),"") -> #REF! | G12: =IF(M12>0,(PROPER(_xlfn.XLOOKUP(M12,#REF!,#REF!,"No encontrado",0))),"") -> #REF! | H12: Ninguna | J12: =_xlfn.XLOOKUP(M12,#REF!,#REF!,0) -> #REF! | K12: =IF(M12>0,TODAY(),"") -> 46217 | M12: 911 | R12: =IF(M12>0,(UPPER(_xlfn.XLOOKUP(M12,#REF!,#REF!,"No encontrado",0))),"") -> #REF!
B13: LENC-25-I 0919 | D13: 20288 | E13: Tomacorriente | G13: FMF | H13: Ninguna | J13: 45929 | K13: =IF(M13>0,TODAY(),"") -> 46217 | M13: 1402 | R13: =IF(M13>0,(UPPER(_xlfn.XLOOKUP(M13,#REF!,#REF!,"No encontrado",0))),"") -> #REF!
B14: LENC-25-I 1018 | D14: 21277 | E14: Tomacorriente 3 lineas | G14: FMF | H14: Ninguna | J14: 45951 | K14: 45989 | M14: 1517 | R14: =IF(M14>0,(UPPER(_xlfn.XLOOKUP(M14,#REF!,#REF!,"No encontrado",0))),"") -> #REF!
B15: LENC-25-I 1018 | D15: 21228 | E15: Tomacorriente 3 lineas | G15: FMF | H15: Ninguna | J15: 45951 | K15: =IF(M11>0,TODAY(),"") -> 46217 | M15: 1517 | R15: =IF(M15>0,(UPPER(_xlfn.XLOOKUP(M15,#REF!,#REF!,"No encontrado",0))),"") -> #REF!
B16: LENC-25-I 0697 | D16: 20299 | E16: Aro de luz | G16: N/E | H16: Ninguna | J16: 45870 | K16: =IF(M12>0,TODAY(),"") -> 46217 | M16: 1066 | R16: =IF(M16>0,(UPPER(_xlfn.XLOOKUP(M16,#REF!,#REF!,"No encontrado",0))),"") -> #REF!
B17: LENC-25-I0697 | D17: 20300 | E17: Aro de luz | G17: N/E | H17: Ninguna | J17: 45871 | K17: =IF(M13>0,TODAY(),"") -> 46217 | M17: 1067 | R17: =IF(M17>0,(UPPER(_xlfn.XLOOKUP(M17,#REF!,#REF!,"No encontrado",0))),"") -> #REF!
H18: Ninguna | K18: =IF(M14>0,TODAY(),"") -> 46217 | M18: 1435 | R18: =IF(M18>0,(UPPER(_xlfn.XLOOKUP(M18,#REF!,#REF!,"No encontrado",0))),"") -> #REF!
H19: Ninguna | K19: =IF(M15>0,TODAY(),"") -> 46217 | M19: 1436 | R19: =IF(M19>0,(UPPER(_xlfn.XLOOKUP(M19,#REF!,#REF!,"No encontrado",0))),"") -> #REF!
H20: Ninguna | M20: 1437 | R20: =IF(M20>0,(UPPER(_xlfn.XLOOKUP(M20,#REF!,#REF!,"No encontrado",0))),"") -> #REF!
H21: Ninguna | M21: 1438
B22: LENC-25-I 0968 | D22: =IF(M18>0,(UPPER(_xlfn.XLOOKUP(M18,#REF!,#REF!,"No encontrado",0))),"") -> #REF! | E22: =IF(M18>0,(PROPER(_xlfn.XLOOKUP(M18,#REF!,#REF!,"No encontrado",0))),"") -> #REF! | G22: =IF(M18>0,(PROPER(_xlfn.XLOOKUP(M18,#REF!,#REF!,"No encontrado",0))),"") -> #REF! | H22: Ninguna | J22: =_xlfn.XLOOKUP(M18,#REF!,#REF!,0) -> #REF! | K22: =IF(M18>0,TODAY(),"") -> 46217 | M22: 1439
B23: LENC-25-I 0968 | D23: =IF(M19>0,(UPPER(_xlfn.XLOOKUP(M19,#REF!,#REF!,"No encontrado",0))),"") -> #REF! | E23: =IF(M19>0,(PROPER(_xlfn.XLOOKUP(M19,#REF!,#REF!,"No encontrado",0))),"") -> #REF! | G23: =IF(M19>0,(PROPER(_xlfn.XLOOKUP(M19,#REF!,#REF!,"No encontrado",0))),"") -> #REF! | H23: Ninguna | J23: =_xlfn.XLOOKUP(M19,#REF!,#REF!,0) -> #REF! | K23: =IF(M19>0,TODAY(),"") -> 46217 | M23: 1440 | R23: =IF(M20>0,(UPPER(_xlfn.XLOOKUP(M20,#REF!,#REF!,"No encontrado",0))),"") -> #REF!
B24: LENC-25-I 0968 | D24: =IF(M20>0,(UPPER(_xlfn.XLOOKUP(M20,#REF!,#REF!,"No encontrado",0))),"") -> #REF! | E24: =IF(M20>0,(PROPER(_xlfn.XLOOKUP(M20,#REF!,#REF!,"No encontrado",0))),"") -> #REF! | G24: =IF(M20>0,(PROPER(_xlfn.XLOOKUP(M20,#REF!,#REF!,"No encontrado",0))),"") -> #REF! | H24: Ninguna | J24: =_xlfn.XLOOKUP(M20,#REF!,#REF!,0) -> #REF! | K24: =IF(M20>0,TODAY(),"") -> 46217 | R24: =IF(M21>0,(UPPER(_xlfn.XLOOKUP(M21,#REF!,#REF!,"No encontrado",0))),"") -> #REF!
B25: LENC-25-I 0969 | D25: =IF(M21>0,(UPPER(_xlfn.XLOOKUP(M21,#REF!,#REF!,"No encontrado",0))),"") -> #REF! | E25: =IF(M21>0,(PROPER(_xlfn.XLOOKUP(M21,#REF!,#REF!,"No encontrado",0))),"") -> #REF! | G25: =IF(M21>0,(PROPER(_xlfn.XLOOKUP(M21,#REF!,#REF!,"No encontrado",0))),"") -> #REF! | H25: Ninguna | J25: =_xlfn.XLOOKUP(M21,#REF!,#REF!,0) -> #REF! | K25: =IF(M21>0,TODAY(),"") -> 46217 | R25: =IF(M22>0,(UPPER(_xlfn.XLOOKUP(M22,#REF!,#REF!,"No encontrado",0))),"") -> #REF!
B26: LENC-25-I 0969 | D26: =IF(M22>0,(UPPER(_xlfn.XLOOKUP(M22,#REF!,#REF!,"No encontrado",0))),"") -> #REF! | E26: =IF(M22>0,(PROPER(_xlfn.XLOOKUP(M22,#REF!,#REF!,"No encontrado",0))),"") -> #REF! | G26: =IF(M22>0,(PROPER(_xlfn.XLOOKUP(M22,#REF!,#REF!,"No encontrado",0))),"") -> #REF! | H26: Ninguna | J26: =_xlfn.XLOOKUP(M22,#REF!,#REF!,0) -> #REF! | K26: =IF(M22>0,TODAY(),"") -> 46217 | R26: =IF(M23>0,(UPPER(_xlfn.XLOOKUP(M23,#REF!,#REF!,"No encontrado",0))),"") -> #REF!
B27: LENC-25-I 0968 | D27: =IF(M23>0,(UPPER(_xlfn.XLOOKUP(M23,#REF!,#REF!,"No encontrado",0))),"") -> #REF! | E27: =IF(M23>0,(PROPER(_xlfn.XLOOKUP(M23,#REF!,#REF!,"No encontrado",0))),"") -> #REF! | G27: =IF(M23>0,(PROPER(_xlfn.XLOOKUP(M23,#REF!,#REF!,"No encontrado",0))),"") -> #REF! | H27: Ninguna | J27: =_xlfn.XLOOKUP(M23,#REF!,#REF!,0) -> #REF! | K27: =IF(M23>0,TODAY(),"") -> 46217 | R27: =IF(M24>0,(UPPER(_xlfn.XLOOKUP(M24,#REF!,#REF!,"No encontrado",0))),"")
B28: LENC-25- I 1008 | D28: 20240 | E28: Tomacorriente con interruptor | G28: Forte | H28: Ninguna | J28: 45938 | K28: =IF(M24>0,TODAY(),"") | R28: =IF(M25>0,(UPPER(_xlfn.XLOOKUP(M25,#REF!,#REF!,"No encontrado",0))),"")
B29: LENC-25- I 1008 | D29: 20249 | E29: Tomacorriente con interruptor | G29: Forte | H29: Ninguna | J29: =_xlfn.XLOOKUP(M25,#REF!,#REF!,0) -> #REF! | K29: =IF(M25>0,TODAY(),"") | R29: =IF(M26>0,(UPPER(_xlfn.XLOOKUP(M26,#REF!,#REF!,"No encontrado",0))),"")
B30: LENC-25- I 1008 | D30: 20237 | E30: Interruptor sencillo | G30: Forte | H30: Ninguna | J30: =_xlfn.XLOOKUP(M26,#REF!,#REF!,0) -> #REF! | K30: =IF(M26>0,TODAY(),"") | R30: =IF(M27>0,(UPPER(_xlfn.XLOOKUP(M27,#REF!,#REF!,"No encontrado",0))),"")
B31: LENC-25- I 1008 | D31: 20235 | E31: Interruptor sencillo | G31: Forte | H31: Ninguna | J31: =_xlfn.XLOOKUP(M27,#REF!,#REF!,0) -> #REF! | K31: =IF(M27>0,TODAY(),"") | R31: =IF(M28>0,(UPPER(_xlfn.XLOOKUP(M28,#REF!,#REF!,"No encontrado",0))),"")
B32: LENC-25- I 1008 | D32: 20248 | E32: Interruptor sencillo | G32: Forte | H32: Ninguna | J32: =_xlfn.XLOOKUP(M28,#REF!,#REF!,0) -> #REF! | K32: =IF(M28>0,TODAY(),"") | R32: =IF(M29>0,(UPPER(_xlfn.XLOOKUP(M29,#REF!,#REF!,"No encontrado",0))),"")
B33: LENC-25- I 1008 | D33: 20247 | E33: Interruptor sencillo | G33: Forte | H33: Ninguna | J33: =_xlfn.XLOOKUP(M29,#REF!,#REF!,0) -> #REF! | K33: =IF(M29>0,TODAY(),"") | R33: =IF(M30>0,(UPPER(_xlfn.XLOOKUP(M30,#REF!,#REF!,"No encontrado",0))),"")
B34: LENC-25- I 1008 | D34: 20243 | E34: Interruptor sencillo | G34: Forte | H34: Ninguna | J34: =_xlfn.XLOOKUP(M30,#REF!,#REF!,0) -> #REF! | K34: =IF(M30>0,TODAY(),"") | R34: =IF(M31>0,(UPPER(_xlfn.XLOOKUP(M31,#REF!,#REF!,"No encontrado",0))),"")
B35: LENC-25- I 1008 | D35: 20244 | E35: Interruptor sencillo | G35: Forte | H35: Ninguna | J35: =_xlfn.XLOOKUP(M31,#REF!,#REF!,0) -> #REF! | K35: =IF(M31>0,TODAY(),"") | R35: =IF(M32>0,(UPPER(_xlfn.XLOOKUP(M32,#REF!,#REF!,"No encontrado",0))),"")
B36: LENC-25- I 1008 | D36: 20245 | E36: Interruptor sencillo | G36: Forte | H36: Ninguna | J36: =_xlfn.XLOOKUP(M32,#REF!,#REF!,0) -> #REF! | K36: =IF(M32>0,TODAY(),"") | R36: =IF(M33>0,(UPPER(_xlfn.XLOOKUP(M33,#REF!,#REF!,"No encontrado",0))),"")
B37: LENC-25- I 1008 | D37: 20245 | E37: Interruptor doble | G37: Forte | H37: Ninguna | J37: =_xlfn.XLOOKUP(M33,#REF!,#REF!,0) -> #REF! | K37: =IF(M33>0,TODAY(),"") | R37: =IF(M34>0,(UPPER(_xlfn.XLOOKUP(M34,#REF!,#REF!,"No encontrado",0))),"")
B38: LENC-25- I 1008 | D38: 20241 | E38: Tomacorriente | G38: Forte | H38: Ninguna | J38: =_xlfn.XLOOKUP(M34,#REF!,#REF!,0) -> #REF! | K38: =IF(M34>0,TODAY(),"") | R38: =IF(M35>0,(UPPER(_xlfn.XLOOKUP(M35,#REF!,#REF!,"No encontrado",0))),"")
B39: LENC-25- I 1008 | D39: 20236 | E39: Tomacorriente | G39: Forte | H39: Ninguna | J39: =_xlfn.XLOOKUP(M35,#REF!,#REF!,0) -> #REF! | K39: =IF(M35>0,TODAY(),"") | R39: =IF(M36>0,(UPPER(_xlfn.XLOOKUP(M36,#REF!,#REF!,"No encontrado",0))),"")
R40: =IF(M13>0,(UPPER(_xlfn.XLOOKUP(M13,#REF!,#REF!,"No encontrado",0))),"") -> #REF! | S40: SI(M12>0;(MAYUSC(BUSCARX(M12;CONTROL_MUESTRAS_2025!A:A;CONTROL_MUESTRAS_2025!F:F;"No encontrado";0)));"")
M45: Todas las muestras fueron ensayadas, por lo tanto, ninguna se encuentra en buen estado, debido al procedimiento de ensayo y manipulación de la muestra. | R45: =IF(M42>0,(UPPER(_xlfn.XLOOKUP(M42,#REF!,#REF!,"No encontrado",0))),"")
B46: TOTAL MUESTRAS | C46: 1 | D46: NUMERO DE EMPAQUES | E46: 1 | F46: OBSERVACIÓN FINAL DE LAS MUESTRAS | R46: =IF(M43>0,(UPPER(_xlfn.XLOOKUP(M43,#REF!,#REF!,"No encontrado",0))),"")
R47: =IF(M44>0,(UPPER(_xlfn.XLOOKUP(M44,#REF!,#REF!,"No encontrado",0))),"")
R48: =IF(M45>0,(UPPER(_xlfn.XLOOKUP(M45,#REF!,#REF!,"No encontrado",0))),"") -> #REF!
C49: ENTREGADO POR: | G49: ENTREGADO A: | R49: =IF(M46>0,(UPPER(_xlfn.XLOOKUP(M46,#REF!,#REF!,"No encontrado",0))),"")
...

Sheet Acta_Destrucción 2024
B1: COPIAR DATOS Y PEGAR EN EL ACTA DESTRUCCIÓN ︾ ︾ ︾ ︾ ︾ | G1: PEGAR AQUÍ ÍTEM ︾
B2: IDENTIFICACIÓN INTERNA | C2: IDENTIFICACIÓN EXTERNA | D2: DESCRIPCIÓN | E2: FECHA RECEPCIÓN | G2: ÍTEM
B3: =_xlfn.XLOOKUP(G3,#REF!,CONCATENATE(#REF!," -",#REF!," -",#REF!),"No encontrado") -> #REF! | C3: =_xlfn.XLOOKUP(G3,#REF!,#REF!) -> #REF! | D3: =_xlfn.XLOOKUP(G3,#REF!,#REF!) -> #REF! | E3: =_xlfn.XLOOKUP(G3,#REF!,#REF!) -> #REF!
B4: =_xlfn.XLOOKUP(G4,#REF!,CONCATENATE(#REF!," -",#REF!," -",#REF!),"No encontrado") -> #REF! | C4: =_xlfn.XLOOKUP(G4,#REF!,#REF!) -> #REF! | D4: =_xlfn.XLOOKUP(G4,#REF!,#REF!) -> #REF! | E4: =_xlfn.XLOOKUP(G4,#REF!,#REF!) -> #REF!
B5: =_xlfn.XLOOKUP(G5,#REF!,CONCATENATE(#REF!," -",#REF!," -",#REF!),"No encontrado") -> #REF! | C5: =_xlfn.XLOOKUP(G5,#REF!,#REF!) -> #REF! | D5: =_xlfn.XLOOKUP(G5,#REF!,#REF!) -> #REF! | E5: =_xlfn.XLOOKUP(G5,#REF!,#REF!) -> #REF!
B6: =_xlfn.XLOOKUP(G6,#REF!,CONCATENATE(#REF!," -",#REF!," -",#REF!),"No encontrado") -> #REF! | C6: =_xlfn.XLOOKUP(G6,#REF!,#REF!) -> #REF! | D6: =_xlfn.XLOOKUP(G6,#REF!,#REF!) -> #REF! | E6: =_xlfn.XLOOKUP(G6,#REF!,#REF!) -> #REF!
B7: =_xlfn.XLOOKUP(G7,#REF!,CONCATENATE(#REF!," -",#REF!," -",#REF!),"No encontrado") -> #REF! | C7: =_xlfn.XLOOKUP(G7,#REF!,#REF!) -> #REF! | D7: =_xlfn.XLOOKUP(G7,#REF!,#REF!) -> #REF! | E7: =_xlfn.XLOOKUP(G7,#REF!,#REF!) -> #REF!
B8: =_xlfn.XLOOKUP(G8,#REF!,CONCATENATE(#REF!," -",#REF!," -",#REF!),"No encontrado") -> #REF! | C8: =_xlfn.XLOOKUP(G8,#REF!,#REF!) -> #REF! | D8: =_xlfn.XLOOKUP(G8,#REF!,#REF!) -> #REF! | E8: =_xlfn.XLOOKUP(G8,#REF!,#REF!) -> #REF!
B9: =_xlfn.XLOOKUP(G9,#REF!,CONCATENATE(#REF!," -",#REF!," -",#REF!),"No encontrado") -> #REF! | C9: =_xlfn.XLOOKUP(G9,#REF!,#REF!) -> #REF! | D9: =_xlfn.XLOOKUP(G9,#REF!,#REF!) -> #REF! | E9: =_xlfn.XLOOKUP(G9,#REF!,#REF!) -> #REF!
B10: =_xlfn.XLOOKUP(G10,#REF!,CONCATENATE(#REF!," -",#REF!," -",#REF!),"No encontrado") -> #REF! | C10: =_xlfn.XLOOKUP(G10,#REF!,#REF!) -> #REF! | D10: =_xlfn.XLOOKUP(G10,#REF!,#REF!) -> #REF! | E10: =_xlfn.XLOOKUP(G10,#REF!,#REF!) -> #REF!
B11: =_xlfn.XLOOKUP(G11,#REF!,CONCATENATE(#REF!," -",#REF!," -",#REF!),"No encontrado") -> #REF! | C11: =_xlfn.XLOOKUP(G11,#REF!,#REF!) -> #REF! | D11: =_xlfn.XLOOKUP(G11,#REF!,#REF!) -> #REF! | E11: =_xlfn.XLOOKUP(G11,#REF!,#REF!) -> #REF!
B12: =_xlfn.XLOOKUP(G12,#REF!,CONCATENATE(#REF!," -",#REF!," -",#REF!),"No encontrado") -> #REF! | C12: =_xlfn.XLOOKUP(G12,#REF!,#REF!) -> #REF! | D12: =_xlfn.XLOOKUP(G12,#REF!,#REF!) -> #REF! | E12: =_xlfn.XLOOKUP(G12,#REF!,#REF!) -> #REF!
B13: =_xlfn.XLOOKUP(G13,#REF!,CONCATENATE(#REF!," -",#REF!," -",#REF!),"No encontrado") -> #REF! | C13: =_xlfn.XLOOKUP(G13,#REF!,#REF!) -> #REF! | D13: =_xlfn.XLOOKUP(G13,#REF!,#REF!) -> #REF! | E13: =_xlfn.XLOOKUP(G13,#REF!,#REF!) -> #REF!
B14: =_xlfn.XLOOKUP(G14,#REF!,CONCATENATE(#REF!," -",#REF!," -",#REF!),"No encontrado") -> #REF! | C14: =_xlfn.XLOOKUP(G14,#REF!,#REF!) -> #REF! | D14: =_xlfn.XLOOKUP(G14,#REF!,#REF!) -> #REF! | E14: =_xlfn.XLOOKUP(G14,#REF!,#REF!) -> #REF!
... B165: =_xlfn.XLOOKUP(G165,#REF!,CONCATENATE(#REF!," -",#REF!," -",#REF!),"No encontrado") -> #REF! | C165: =_xlfn.XLOOKUP(G165,#REF!,#REF!) -> #REF! | D165: =_xlfn.XLOOKUP(G165,#REF!,#REF!) -> #REF! | E165: =_xlfn.XLOOKUP(G165,#REF!,#REF!) -> #REF!

Sheet DATOS
A1: CONTROL MUESTRAS 2026 | B1: xxxxxx | D1: Lista desplegable ESTADO DE MUESTRAS
A2: CELDA CONCATENADA | B2: ITEM
D3: Almacenado
D4: Realizar disposición final
D5: En custodia
D6: En curso
D7: Laboratorio Externo
D8: Enviado
D9: Destrución
D19: Lista desplegable Remisiones
D20: TIPO DE SALIDA
D21: ENVIO POR TRASNPORTADORA
D22: RECOLECCIÓN POR PARTE DEL CLIENTE
D23: OTRO
